Workbook

Sheet Dashboard
A1: VISIONBLOX COMMAND CENTER | CAGE 9Z4X2 | UEI H4X2Z7R9E3E3
A2: Phase 0 — Operations & Performance Dashboard | Updated daily | Source-of-truth: this workbook
B4: As-of Date: | C4: 46174 | D4: ← change this to view different snapshot
B6: FINANCIAL REALITY
C7: Year-1 ARR Target | D7: Revenue Booked YTD | E7: Run-Rate P/L (current) | F7: Gap to Break-Even | G7: Gap to ARR Target
C8: =Targets!C5 -> 500000 | D8: =SUMIFS(Revenue_Ledger!E:E,Revenue_Ledger!A:A,">="&DATE(YEAR(As_Of_Date),1,1),Revenue_Ledger!A:A,"<="&As_Of_Date) -> 68500 | E8: =Targets!C12 -> -47870 | F8: =Targets!C13 -> 47870 | G8: =Targets!C14 -> 335600
B10: OPERATIONS
C11: Active Pipeline (#) | D11: Active Pipeline ($) | E11: Active Projects | F11: NDAs Executed YTD
C12: =SUMPRODUCT((Pipeline!E5:E1000<>"")*(Pipeline!E5:E1000<>"Awarded")*(Pipeline!E5:E1000<>"Lost")) -> 8 | D12: =SUMIFS(Pipeline!F5:F1000,Pipeline!E5:E1000,"<>Awarded",Pipeline!E5:E1000,"<>Lost",Pipeline!E5:E1000,"<>") -> 14500000 | E12: =COUNTIFS(Active_Projects!H:H,"Active") -> 0 | F12: =COUNTIFS(NDAs!D:D,">="&DATE(YEAR(As_Of_Date),1,1),NDAs!D:D,"<="&As_Of_Date) -> 19
B14: BD CADENCE — TRAILING WINDOWS
B15: KPI | C15: T-7d | D15: Prior 7d | E15: WoW Δ% | F15: T-30d | G15: Prior 30d | H15: MoM Δ% | I15: Target /mo | J15: vs Target
B16: Screenings | C16: =Metrics_Period!C5 -> 7 | D16: =Metrics_Period!D5 -> 1 | E16: =Metrics_Period!E5 -> 6 | F16: =Metrics_Period!F5 -> 14 | G16: =Metrics_Period!G5 -> 36 | H16: =Metrics_Period!H5 -> -0.61111111 | I16: =Metrics_Period!I5 -> 26 | J16: =Metrics_Period!J5 -> -0.46153846
B17: NDAs | C17: =Metrics_Period!C6 -> 0 | D17: =Metrics_Period!D6 -> 1 | E17: =Metrics_Period!E6 -> -1 | F17: =Metrics_Period!F6 -> 6 | G17: =Metrics_Period!G6 -> 13 | H17: =Metrics_Period!H6 -> -0.53846154 | I17: =Metrics_Period!I6 -> 9 | J17: =Metrics_Period!J6 -> -0.33333333
B18: Agreements | C18: =Metrics_Period!C7 -> 0 | D18: =Metrics_Period!D7 -> 0 | E18: =Metrics_Period!E7 -> 0 | F18: =Metrics_Period!F7 -> 1 | G18: =Metrics_Period!G7 -> 0 | H18: =Metrics_Period!H7 -> 0 | I18: =Metrics_Period!I7 -> 9 | J18: =Metrics_Period!J7 -> -0.88888889
B19: Meetings | C19: =Metrics_Period!C8 -> 8 | D19: =Metrics_Period!D8 -> 4 | E19: =Metrics_Period!E8 -> 1 | F19: =Metrics_Period!F8 -> 25 | G19: =Metrics_Period!G8 -> 19 | H19: =Metrics_Period!H8 -> 0.31578947 | I19: =Metrics_Period!I8 -> 9 | J19: =Metrics_Period!J8 -> 1.7777778
B20: New Pipeline Opps | C20: =Metrics_Period!C9 -> 0 | D20: =Metrics_Period!D9 -> 2 | E20: =Metrics_Period!E9 -> -1 | F20: =Metrics_Period!F9 -> 3 | G20: =Metrics_Period!G9 -> 2 | H20: =Metrics_Period!H9 -> 0.5 | I20: =Metrics_Period!I9 -> 4 | J20: =Metrics_Period!J9 -> -0.25
B22: FINANCIAL CADENCE — ACTUAL vs TARGET
B23: Metric | C23: T-7d | D23: Prior 7d | E23: WoW Δ% | F23: T-30d | G23: Prior 30d | H23: MoM Δ% | I23: T-91d | J23: YTD
B24: Revenue ($) — actual | C24: =Metrics_Period!C13 -> 13700 | D24: =Metrics_Period!D13 -> 0 | E24: =Metrics_Period!E13 -> 0 | F24: =Metrics_Period!F13 -> 13700 | G24: =Metrics_Period!G13 -> 13700 | H24: =Metrics_Period!H13 -> 0 | I24: =Metrics_Period!K13 -> 41100 | J24: =Metrics_Period!L13 -> 68500
B25: Expenses ($) — actual | C25: =Metrics_Period!C14 -> 0 | D25: =Metrics_Period!D14 -> 0 | E25: =Metrics_Period!E14 -> 0 | F25: =Metrics_Period!F14 -> 0 | G25: =Metrics_Period!G14 -> 0 | H25: =Metrics_Period!H14 -> 0 | I25: =Metrics_Period!K14 -> 0 | J25: =Metrics_Period!L14 -> 0
B26: Net P/L ($) — actuals only | C26: =Metrics_Period!C15 -> 13700 | D26: =Metrics_Period!D15 -> 0 | E26: =Metrics_Period!E15 -> 0 | F26: =Metrics_Period!F15 -> 13700 | G26: =Metrics_Period!G15 -> 13700 | H26: =Metrics_Period!H15 -> 0 | I26: =Metrics_Period!K15 -> 41100 | J26: =Metrics_Period!L15 -> 68500
B27: Expenses ($) — budgeted | C27: =Targets!C6/365*7 -> 4070.9315 | D27: =Targets!C6/365*7 -> 4070.9315 | E27: =0 -> 0 | F27: =Targets!C6/365*30 -> 17446.849 | G27: =Targets!C6/365*30 -> 17446.849 | H27: =0 -> 0 | I27: =Targets!C6/365*91 -> 52922.11 | J27: =Targets!C6/365*(As_Of_Date-DATE(YEAR(As_Of_Date),1,1)+1) -> 88397.37
B28: Net P/L ($) — actual rev vs budget exp | C28: =C24-C27 -> 9629.0685 | D28: =D24-D27 -> -4070.9315 | E28: =IFERROR((C28-D28)/IF(D28=0,1,ABS(D28)),0) -> 3.3653231 | F28: =F24-F27 -> -3746.8493 | G28: =G24-G27 -> -3746.8493 | H28: =IFERROR((F28-G28)/IF(G28=0,1,ABS(G28)),0) -> 0 | I28: =I24-I27 -> -11822.11 | J28: =J24-J27 -> -19897.37
B30: ⚠ Net P/L (actuals-only) is partial: Expense_Ledger has no entries yet. The "actual rev vs budget exp" row below uses pro-rated annual budget ($212,270 ÷ 365) as an expense proxy — closer to economic reality until you log actual expenses.
B32: ACTIVE BLOCKERS — PIPELINE GATING ITEMS
B33: • WA Secretary of State foreign entity registration (~$180) — gates all WA SLED work
B34: • eMMA registration (Maryland) — gates Maryland SLED pursuits including BPM054667
B35: • SOC 2 Type II gap assessment — recurring DQ on WA + select federal
B36: • GSA MAS 54151HEAL Refresh 31 remediation (7 deficiencies open)
B37: • Advocate IT teaming agreement (Thomas Duffy) — not executed

Sheet Targets
A1: TARGETS — Internal Goals & KPI Reference
A2: Edit values in BLUE to update goals. Formulas in BLACK should not be edited.
B4: FINANCIAL TARGETS (Year 1)
B5: Year-1 ARR Target | C5: 500000 | D5: New top-line goal — overrides income-statement projection
B6: Yearly Expense Budget | C6: 212270 | D6: Source: income statement (sum of expense lines)
B7: Yearly P/L Target | C7: =C5-C6 -> 287730 | D7: Aspirational: P/L if Year-1 ARR target is achieved
B9: Confirmed Revenue: HCPSS | C9: 134400 | D9: Source: income statement
B10: Confirmed Revenue: First Brands Group | C10: 30000 | D10: Source: income statement
B11: Subtotal Confirmed Revenue | C11: =C9+C10 -> 164400 | D11: Sum of confirmed contracts
B12: Run-Rate P/L (Confirmed − Budget) | C12: =C11-C6 -> -47870 | D12: Current burn from confirmed contracts only — matches income-statement bottom line
B13: Gap to Break-Even | C13: =MAX(C6-C11,0) -> 47870 | D13: New revenue needed to stop losing money (cross break-even)
B14: Gap to ARR Target (must win) | C14: =C5-C11 -> 335600 | D14: Amount of new business needed to hit Y1 ARR target
B17: MONTHLY TARGET SCHEDULE (flat allocation = Annual ÷ 12)
B18: Month | C18: Revenue Target | D18: Expense Target | E18: P/L Target | F18: Cumulative Revenue Target
B19: Jan | C19: =$C$5/12 -> 41666.667 | D19: =$C$6/12 -> 17689.167 | E19: =C19-D19 -> 23977.5 | F19: =C19 -> 41666.667
B20: Feb | C20: =$C$5/12 -> 41666.667 | D20: =$C$6/12 -> 17689.167 | E20: =C20-D20 -> 23977.5 | F20: =F19+C20 -> 83333.333
B21: Mar | C21: =$C$5/12 -> 41666.667 | D21: =$C$6/12 -> 17689.167 | E21: =C21-D21 -> 23977.5 | F21: =F20+C21 -> 125000
B22: Apr | C22: =$C$5/12 -> 41666.667 | D22: =$C$6/12 -> 17689.167 | E22: =C22-D22 -> 23977.5 | F22: =F21+C22 -> 166666.67
B23: May | C23: =$C$5/12 -> 41666.667 | D23: =$C$6/12 -> 17689.167 | E23: =C23-D23 -> 23977.5 | F23: =F22+C23 -> 208333.33
B24: Jun | C24: =$C$5/12 -> 41666.667 | D24: =$C$6/12 -> 17689.167 | E24: =C24-D24 -> 23977.5 | F24: =F23+C24 -> 250000
B25: Jul | C25: =$C$5/12 -> 41666.667 | D25: =$C$6/12 -> 17689.167 | E25: =C25-D25 -> 23977.5 | F25: =F24+C25 -> 291666.67
B26: Aug | C26: =$C$5/12 -> 41666.667 | D26: =$C$6/12 -> 17689.167 | E26: =C26-D26 -> 23977.5 | F26: =F25+C26 -> 333333.33
B27: Sep | C27: =$C$5/12 -> 41666.667 | D27: =$C$6/12 -> 17689.167 | E27: =C27-D27 -> 23977.5 | F27: =F26+C27 -> 375000
B28: Oct | C28: =$C$5/12 -> 41666.667 | D28: =$C$6/12 -> 17689.167 | E28: =C28-D28 -> 23977.5 | F28: =F27+C28 -> 416666.67
B29: Nov | C29: =$C$5/12 -> 41666.667 | D29: =$C$6/12 -> 17689.167 | E29: =C29-D29 -> 23977.5 | F29: =F28+C29 -> 458333.33
B30: Dec | C30: =$C$5/12 -> 41666.667 | D30: =$C$6/12 -> 17689.167 | E30: =C30-D30 -> 23977.5 | F30: =F29+C30 -> 500000
B32: BD CADENCE TARGETS
B33: KPI | C33: Weekly | D33: Monthly (×4.33) | E33: Quarterly (×13) | F33: Annual | G33: Notes
B34: Screenings | C34: 6 | D34: =ROUND(C34*4.33,0) -> 26 | E34: =C34*13 -> 78 | F34: =C34*52 -> 312 | G34: Run rate Apr 1 → Jun 1 = 6.2/wk
B35: NDAs Executed | C35: 2 | D35: =ROUND(C35*4.33,0) -> 9 | E35: =C35*13 -> 26 | F35: =C35*52 -> 104 | G35: Run rate = 2.1/wk
B36: Agreements Executed | C36: 2 | D36: =ROUND(C36*4.33,0) -> 9 | E36: =C36*13 -> 26 | F36: =C36*52 -> 104 | G36: Teaming/commission/partnership; run rate = 1.9/wk
B37: Meetings | C37: 2 | D37: =ROUND(C37*4.33,0) -> 9 | E37: =C37*13 -> 26 | F37: =C37*52 -> 104 | G37: Discovery + sync + capture meetings
B38: New Pipeline Opps | C38: 1 | D38: =ROUND(C38*4.33,0) -> 4 | E38: =C38*13 -> 13 | F38: =C38*52 -> 52 | G38: Net new opportunities entered into pipeline
B41: PIPELINE COVERAGE TARGET (steady-state stock, not flow)
B42: Active Pipeline Opportunities Tracked | C42: 20 | D42: Conservative for one-capture-manager BD (Khaalis), assumes ~25% win rate on submitted opps

Sheet Metrics_Period
A1: METRICS_PERIOD — Computed Engine (Do not edit — formula-driven)
A2: All values driven by As_Of_Date on Dashboard. Pulls from input ledgers via SUMIFS/COUNTIFS.
A4: # | B4: KPI | C4: T-7d | D4: Prior 7d | E4: WoW Δ% | F4: T-30d | G4: Prior 30d | H4: MoM Δ% | I4: Target /mo | J4: vs Target | K4: T-91d | L4: Prior 91d / YTD | M4: QoQ Δ% | N4: YoY Δ%
A5: 1 | B5: Screenings | C5: =COUNTIFS(Screenings!E:E,">="&As_Of_Date-7,Screenings!E:E,"<="&As_Of_Date-0) -> 7 | D5: =COUNTIFS(Screenings!E:E,">="&As_Of_Date-14,Screenings!E:E,"<"&As_Of_Date-7) -> 1 | E5: =IFERROR((C5-D5)/D5,0) -> 6 | F5: =COUNTIFS(Screenings!E:E,">="&As_Of_Date-30,Screenings!E:E,"<="&As_Of_Date-0) -> 14 | G5: =COUNTIFS(Screenings!E:E,">="&As_Of_Date-60,Screenings!E:E,"<"&As_Of_Date-30) -> 36 | H5: =IFERROR((F5-G5)/G5,0) -> -0.61111111 | I5: =Targets!D34 -> 26 | J5: =IFERROR((F5-I5)/I5,0) -> -0.46153846 | K5: =COUNTIFS(Screenings!E:E,">="&As_Of_Date-91,Screenings!E:E,"<="&As_Of_Date-0) -> 54 | L5: =COUNTIFS(Screenings!E:E,">="&As_Of_Date-182,Screenings!E:E,"<"&As_Of_Date-91) -> 0 | M5: =IFERROR((K5-L5)/L5,0) -> 0 | N5: =IFERROR((COUNTIFS(Screenings!E:E,">="&As_Of_Date-365,Screenings!E:E,"<="&As_Of_Date-0)-COUNTIFS(Screenings!E:E,">="&As_Of_Date-730,Screenings!E:E,"<"&As_Of_Date-365))/COUNTIFS(Screenings!E:E,">="&As_Of_Date-730,Screenings!E:E,"<"&As_Of_Date-365),0) -> 0
A6: 2 | B6: NDAs | C6: =COUNTIFS(NDAs!D:D,">="&As_Of_Date-7,NDAs!D:D,"<="&As_Of_Date-0) -> 0 | D6: =COUNTIFS(NDAs!D:D,">="&As_Of_Date-14,NDAs!D:D,"<"&As_Of_Date-7) -> 1 | E6: =IFERROR((C6-D6)/D6,0) -> -1 | F6: =COUNTIFS(NDAs!D:D,">="&As_Of_Date-30,NDAs!D:D,"<="&As_Of_Date-0) -> 6 | G6: =COUNTIFS(NDAs!D:D,">="&As_Of_Date-60,NDAs!D:D,"<"&As_Of_Date-30) -> 13 | H6: =IFERROR((F6-G6)/G6,0) -> -0.53846154 | I6: =Targets!D35 -> 9 | J6: =IFERROR((F6-I6)/I6,0) -> -0.33333333 | K6: =COUNTIFS(NDAs!D:D,">="&As_Of_Date-91,NDAs!D:D,"<="&As_Of_Date-0) -> 19 | L6: =COUNTIFS(NDAs!D:D,">="&As_Of_Date-182,NDAs!D:D,"<"&As_Of_Date-91) -> 0 | M6: =IFERROR((K6-L6)/L6,0) -> 0 | N6: =IFERROR((COUNTIFS(NDAs!D:D,">="&As_Of_Date-365,NDAs!D:D,"<="&As_Of_Date-0)-COUNTIFS(NDAs!D:D,">="&As_Of_Date-730,NDAs!D:D,"<"&As_Of_Date-365))/COUNTIFS(NDAs!D:D,">="&As_Of_Date-730,NDAs!D:D,"<"&As_Of_Date-365),0) -> 0
A7: 3 | B7: Agreements | C7: =COUNTIFS(Agreements!D:D,">="&As_Of_Date-7,Agreements!D:D,"<="&As_Of_Date-0) -> 0 | D7: =COUNTIFS(Agreements!D:D,">="&As_Of_Date-14,Agreements!D:D,"<"&As_Of_Date-7) -> 0 | E7: =IFERROR((C7-D7)/D7,0) -> 0 | F7: =COUNTIFS(Agreements!D:D,">="&As_Of_Date-30,Agreements!D:D,"<="&As_Of_Date-0) -> 1 | G7: =COUNTIFS(Agreements!D:D,">="&As_Of_Date-60,Agreements!D:D,"<"&As_Of_Date-30) -> 0 | H7: =IFERROR((F7-G7)/G7,0) -> 0 | I7: =Targets!D36 -> 9 | J7: =IFERROR((F7-I7)/I7,0) -> -0.88888889 | K7: =COUNTIFS(Agreements!D:D,">="&As_Of_Date-91,Agreements!D:D,"<="&As_Of_Date-0) -> 1 | L7: =COUNTIFS(Agreements!D:D,">="&As_Of_Date-182,Agreements!D:D,"<"&As_Of_Date-91) -> 0 | M7: =IFERROR((K7-L7)/L7,0) -> 0 | N7: =IFERROR((COUNTIFS(Agreements!D:D,">="&As_Of_Date-365,Agreements!D:D,"<="&As_Of_Date-0)-COUNTIFS(Agreements!D:D,">="&As_Of_Date-730,Agreements!D:D,"<"&As_Of_Date-365))/COUNTIFS(Agreements!D:D,">="&As_Of_Date-730,Agreements!D:D,"<"&As_Of_Date-365),0) -> 0
A8: 4 | B8: Meetings | C8: =COUNTIFS(Meetings!A:A,">="&As_Of_Date-7,Meetings!A:A,"<="&As_Of_Date-0) -> 8 | D8: =COUNTIFS(Meetings!A:A,">="&As_Of_Date-14,Meetings!A:A,"<"&As_Of_Date-7) -> 4 | E8: =IFERROR((C8-D8)/D8,0) -> 1 | F8: =COUNTIFS(Meetings!A:A,">="&As_Of_Date-30,Meetings!A:A,"<="&As_Of_Date-0) -> 25 | G8: =COUNTIFS(Meetings!A:A,">="&As_Of_Date-60,Meetings!A:A,"<"&As_Of_Date-30) -> 19 | H8: =IFERROR((F8-G8)/G8,0) -> 0.31578947 | I8: =Targets!D37 -> 9 | J8: =IFERROR((F8-I8)/I8,0) -> 1.7777778 | K8: =COUNTIFS(Meetings!A:A,">="&As_Of_Date-91,Meetings!A:A,"<="&As_Of_Date-0) -> 49 | L8: =COUNTIFS(Meetings!A:A,">="&As_Of_Date-182,Meetings!A:A,"<"&As_Of_Date-91) -> 6 | M8: =IFERROR((K8-L8)/L8,0) -> 7.1666667 | N8: =IFERROR((COUNTIFS(Meetings!A:A,">="&As_Of_Date-365,Meetings!A:A,"<="&As_Of_Date-0)-COUNTIFS(Meetings!A:A,">="&As_Of_Date-730,Meetings!A:A,"<"&As_Of_Date-365))/COUNTIFS(Meetings!A:A,">="&As_Of_Date-730,Meetings!A:A,"<"&As_Of_Date-365),0) -> 0
A9: 5 | B9: New Pipeline Opps | C9: =COUNTIFS(Pipeline!G:G,">="&As_Of_Date-7,Pipeline!G:G,"<="&As_Of_Date-0) -> 0 | D9: =COUNTIFS(Pipeline!G:G,">="&As_Of_Date-14,Pipeline!G:G,"<"&As_Of_Date-7) -> 2 | E9: =IFERROR((C9-D9)/D9,0) -> -1 | F9: =COUNTIFS(Pipeline!G:G,">="&As_Of_Date-30,Pipeline!G:G,"<="&As_Of_Date-0) -> 3 | G9: =COUNTIFS(Pipeline!G:G,">="&As_Of_Date-60,Pipeline!G:G,"<"&As_Of_Date-30) -> 2 | H9: =IFERROR((F9-G9)/G9,0) -> 0.5 | I9: =Targets!D38 -> 4 | J9: =IFERROR((F9-I9)/I9,0) -> -0.25 | K9: =COUNTIFS(Pipeline!G:G,">="&As_Of_Date-91,Pipeline!G:G,"<="&As_Of_Date-0) -> 5 | L9: =COUNTIFS(Pipeline!G:G,">="&As_Of_Date-182,Pipeline!G:G,"<"&As_Of_Date-91) -> 0 | M9: =IFERROR((K9-L9)/L9,0) -> 0 | N9: =IFERROR((COUNTIFS(Pipeline!G:G,">="&As_Of_Date-365,Pipeline!G:G,"<="&As_Of_Date-0)-COUNTIFS(Pipeline!G:G,">="&As_Of_Date-730,Pipeline!G:G,"<"&As_Of_Date-365))/COUNTIFS(Pipeline!G:G,">="&As_Of_Date-730,Pipeline!G:G,"<"&As_Of_Date-365),0) -> 0
B12: FINANCIAL METRICS
A13: 1 | B13: Revenue ($) | C13: =SUMIFS(Revenue_Ledger!E:E,Revenue_Ledger!A:A,">="&As_Of_Date-7,Revenue_Ledger!A:A,"<="&As_Of_Date-0) -> 13700 | D13: =SUMIFS(Revenue_Ledger!E:E,Revenue_Ledger!A:A,">="&As_Of_Date-14,Revenue_Ledger!A:A,"<"&As_Of_Date-7) -> 0 | E13: =IFERROR((C13-D13)/D13,0) -> 0 | F13: =SUMIFS(Revenue_Ledger!E:E,Revenue_Ledger!A:A,">="&As_Of_Date-30,Revenue_Ledger!A:A,"<="&As_Of_Date-0) -> 13700 | G13: =SUMIFS(Revenue_Ledger!E:E,Revenue_Ledger!A:A,">="&As_Of_Date-60,Revenue_Ledger!A:A,"<"&As_Of_Date-30) -> 13700 | H13: =IFERROR((F13-G13)/G13,0) -> 0 | I13: =Targets!C5/12 -> 41666.667 | J13: =IFERROR((F13-I13)/I13,0) -> -0.6712 | K13: =SUMIFS(Revenue_Ledger!E:E,Revenue_Ledger!A:A,">="&As_Of_Date-91,Revenue_Ledger!A:A,"<="&As_Of_Date-0) -> 41100 | L13: =SUMIFS(Revenue_Ledger!E:E,Revenue_Ledger!A:A,">="&DATE(YEAR(As_Of_Date),1,1),Revenue_Ledger!A:A,"<="&As_Of_Date) -> 68500 | M13: =IFERROR((K13-SUMIFS(Revenue_Ledger!E:E,Revenue_Ledger!A:A,">="&As_Of_Date-182,Revenue_Ledger!A:A,"<"&As_Of_Date-91))/SUMIFS(Revenue_Ledger!E:E,Revenue_Ledger!A:A,">="&As_Of_Date-182,Revenue_Ledger!A:A,"<"&As_Of_Date-91),0) -> 0.5 | N13: =IFERROR((SUMIFS(Revenue_Ledger!E:E,Revenue_Ledger!A:A,">="&As_Of_Date-365,Revenue_Ledger!A:A,"<="&As_Of_Date-0)-SUMIFS(Revenue_Ledger!E:E,Revenue_Ledger!A:A,">="&As_Of_Date-730,Revenue_Ledger!A:A,"<"&As_Of_Date-365))/SUMIFS(Revenue_Ledger!E:E,Revenue_Ledger!A:A,">="&As_Of_Date-730,Revenue_Ledger!A:A,"<"&As_Of_Date-365),0) -> 0
A14: 2 | B14: Expenses ($) | C14: =SUMIFS(Expense_Ledger!D:D,Expense_Ledger!A:A,">="&As_Of_Date-7,Expense_Ledger!A:A,"<="&As_Of_Date-0) -> 0 | D14: =SUMIFS(Expense_Ledger!D:D,Expense_Ledger!A:A,">="&As_Of_Date-14,Expense_Ledger!A:A,"<"&As_Of_Date-7) -> 0 | E14: =IFERROR((C14-D14)/D14,0) -> 0 | F14: =SUMIFS(Expense_Ledger!D:D,Expense_Ledger!A:A,">="&As_Of_Date-30,Expense_Ledger!A:A,"<="&As_Of_Date-0) -> 0 | G14: =SUMIFS(Expense_Ledger!D:D,Expense_Ledger!A:A,">="&As_Of_Date-60,Expense_Ledger!A:A,"<"&As_Of_Date-30) -> 0 | H14: =IFERROR((F14-G14)/G14,0) -> 0 | I14: =Targets!C6/12 -> 17689.167 | J14: =IFERROR((F14-I14)/I14,0) -> -1 | K14: =SUMIFS(Expense_Ledger!D:D,Expense_Ledger!A:A,">="&As_Of_Date-91,Expense_Ledger!A:A,"<="&As_Of_Date-0) -> 0 | L14: =SUMIFS(Expense_Ledger!D:D,Expense_Ledger!A:A,">="&DATE(YEAR(As_Of_Date),1,1),Expense_Ledger!A:A,"<="&As_Of_Date) -> 0 | M14: =IFERROR((K14-SUMIFS(Expense_Ledger!D:D,Expense_Ledger!A:A,">="&As_Of_Date-182,Expense_Ledger!A:A,"<"&As_Of_Date-91))/SUMIFS(Expense_Ledger!D:D,Expense_Ledger!A:A,">="&As_Of_Date-182,Expense_Ledger!A:A,"<"&As_Of_Date-91),0) -> 0 | N14: =IFERROR((SUMIFS(Expense_Ledger!D:D,Expense_Ledger!A:A,">="&As_Of_Date-365,Expense_Ledger!A:A,"<="&As_Of_Date-0)-SUMIFS(Expense_Ledger!D:D,Expense_Ledger!A:A,">="&As_Of_Date-730,Expense_Ledger!A:A,"<"&As_Of_Date-365))/SUMIFS(Expense_Ledger!D:D,Expense_Ledger!A:A,">="&As_Of_Date-730,Expense_Ledger!A:A,"<"&As_Of_Date-365),0) -> 0
A15: 3 | B15: Net P/L ($) | C15: =C13-C14 -> 13700 | D15: =D13-D14 -> 0 | E15: =IFERROR((C15-D15)/D15,0) -> 0 | F15: =F13-F14 -> 13700 | G15: =G13-G14 -> 13700 | H15: =IFERROR((F15-G15)/G15,0) -> 0 | I15: =I13-I14 -> 23977.5 | J15: =IFERROR((F15-I15)/IF(I15=0,1,ABS(I15)),0) -> -0.42863101 | K15: =K13-K14 -> 41100 | L15: =L13-L14 -> 68500 | M15: =IFERROR((K15-((SUMIFS(Revenue_Ledger!E:E,Revenue_Ledger!A:A,">="&As_Of_Date-182,Revenue_Ledger!A:A,"<"&As_Of_Date-91))-(SUMIFS(Expense_Ledger!D:D,Expense_Ledger!A:A,">="&As_Of_Date-182,Expense_Ledger!A:A,"<"&As_Of_Date-91))))/IF(((SUMIFS(Revenue_Ledger!E:E,Revenue_Ledger!A:A,">="&As_Of_Date-182,Revenue_Ledger!A:A,"<"&As_Of_Date-91))-(SUMIFS(Expense_Ledger!D:D,Expense_Ledger!A:A,">="&As_Of_Date-182,Expense_Ledger!A:A,"<"&As_Of_Date-91)))=0,1,ABS((SUMIFS(Revenue_Ledger!E:E,Revenue_Ledger!A:A,">="&As_Of_Date-182,Revenue_Ledger!A:A,"<"&As_Of_Date-91))-(SUMIFS(Expense_Ledger!D:D,Expense_Ledger!A:A,">="&As_Of_Date-182,Expense_Ledger!A:A,"<"&As_Of_Date-91)))),0) -> 0.5 | N15: 0
B18: Legend:
B19: • T-7d = trailing 7 days through As_Of_Date | Prior 7d = the 7 days before that
B20: • T-30d, T-91d, T-365d same logic. YoY uses 365-day windows.
B21: • "vs Target" compares T-30d actual against monthly target (negative = behind plan).
B22: • Pipeline opp counts use "Date Identified" (col G on Pipeline sheet).

Sheet Revenue_Ledger
A1: REVENUE LEDGER — Add one row per invoice
A2: Add new rows as invoices are issued. "Amount Invoiced" feeds revenue metrics. Payments tracked for cash-flow view.
A4: Invoice Date | B4: Client | C4: Contract # | D4: Invoice # | E4: Amount Invoiced | F4: Amount Paid | G4: Payment Date | H4: Notes
A5: 46053 | B5: HCPSS | C5: HCPSS-2026-CY | D5: INV-2026-001 | E5: 11200 | F5: 11200 | G5: 46083 | H5: Monthly retainer — Jan 2026
A6: 46053 | B6: First Brands Group | C6: FBG-2026-CY | D6: INV-2026-002 | E6: 2500 | F6: 2500 | G6: 46083 | H6: Monthly retainer — Jan 2026
A7: 46081 | B7: HCPSS | C7: HCPSS-2026-CY | D7: INV-2026-003 | E7: 11200 | F7: 11200 | G7: 46111 | H7: Monthly retainer — Feb 2026
A8: 46081 | B8: First Brands Group | C8: FBG-2026-CY | D8: INV-2026-004 | E8: 2500 | F8: 2500 | G8: 46111 | H8: Monthly retainer — Feb 2026
A9: 46112 | B9: HCPSS | C9: HCPSS-2026-CY | D9: INV-2026-005 | E9: 11200 | F9: 11200 | G9: 46142 | H9: Monthly retainer — Mar 2026
A10: 46112 | B10: First Brands Group | C10: FBG-2026-CY | D10: INV-2026-006 | E10: 2500 | F10: 2500 | G10: 46142 | H10: Monthly retainer — Mar 2026
A11: 46142 | B11: HCPSS | C11: HCPSS-2026-CY | D11: INV-2026-007 | E11: 11200 | F11: 11200 | G11: 46171 | H11: Monthly retainer — Apr 2026
A12: 46142 | B12: First Brands Group | C12: FBG-2026-CY | D12: INV-2026-008 | E12: 2500 | F12: 2500 | G12: 46171 | H12: Monthly retainer — Apr 2026
A13: 46173 | B13: HCPSS | C13: HCPSS-2026-CY | D13: INV-2026-009 | E13: 11200 | H13: Monthly retainer — May 2026 (payment pending)
A14: 46173 | B14: First Brands Group | C14: FBG-2026-CY | D14: INV-2026-010 | E14: 2500 | H14: Monthly retainer — May 2026 (payment pending)

Sheet Expense_Ledger
A1: EXPENSE LEDGER — Add one row per expense
A2: Categories mirror the income statement: Payroll, Office, Marketing & BD, Travel, Software, Taxes, Miscellaneous.
A4: Date | B4: Category | C4: Sub-Category | D4: Amount | E4: Vendor | F4: Notes

Sheet Meetings
A1: MEETINGS LOG — All capture, sync, intro & post-award meetings
A2: Target: 2 meetings/week. Type values: Intro | Sync | Capture | Post-Award | Internal | Customer
A4: Date | B4: Partner / Entity | C4: Attendees (VBX side) | D4: Type | E4: Outcome / Notes | F4: Next Step | G4: Owner
A5: 46043 | B5: AG Grace Inc. | C5: Khaalis Wooden, Susan Rouse, Graham | D5: Sync | E5: Weekly Wednesday partner sync — capture, compliance, set-aside coordination | F5: Continue weekly cadence | G5: Khaalis
A6: 46050 | B6: AG Grace Inc. | C6: Khaalis Wooden, Susan Rouse, Graham | D6: Sync | E6: Weekly Wednesday partner sync — capture, compliance, set-aside coordination | F6: Continue weekly cadence | G6: Khaalis
A7: 46057 | B7: AG Grace Inc. | C7: Khaalis Wooden, Susan Rouse, Graham | D7: Sync | E7: Weekly Wednesday partner sync — capture, compliance, set-aside coordination | F7: Continue weekly cadence | G7: Khaalis
A8: 46064 | B8: AG Grace Inc. | C8: Khaalis Wooden, Susan Rouse, Graham | D8: Sync | E8: Weekly Wednesday partner sync — capture, compliance, set-aside coordination | F8: Continue weekly cadence | G8: Khaalis
A9: 46071 | B9: AG Grace Inc. | C9: Khaalis Wooden, Susan Rouse, Graham | D9: Sync | E9: Weekly Wednesday partner sync — capture, compliance, set-aside coordination | F9: Continue weekly cadence | G9: Khaalis
A10: 46078 | B10: AG Grace Inc. | C10: Khaalis Wooden, Susan Rouse, Graham | D10: Sync | E10: Weekly Wednesday partner sync — capture, compliance, set-aside coordination | F10: Continue weekly cadence | G10: Khaalis
A11: 46085 | B11: AG Grace Inc. | C11: Khaalis Wooden, Susan Rouse, Graham | D11: Sync | E11: Weekly Wednesday partner sync — capture, compliance, set-aside coordination | F11: Continue weekly cadence | G11: Khaalis
A12: 46092 | B12: AG Grace Inc. | C12: Khaalis Wooden, Susan Rouse, Graham | D12: Sync | E12: Weekly Wednesday partner sync — capture, compliance, set-aside coordination | F12: Continue weekly cadence | G12: Khaalis
A13: 46099 | B13: AG Grace Inc. | C13: Khaalis Wooden, Susan Rouse, Graham | D13: Sync | E13: Weekly Wednesday partner sync — capture, compliance, set-aside coordination | F13: Continue weekly cadence | G13: Khaalis
A14: 46106 | B14: AG Grace Inc. | C14: Khaalis Wooden, Susan Rouse, Graham | D14: Sync | E14: Weekly Wednesday partner sync — capture, compliance, set-aside coordination | F14: Continue weekly cadence | G14: Khaalis
A15: 46113 | B15: AG Grace Inc. | C15: Khaalis Wooden, Susan Rouse, Graham | D15: Sync | E15: Weekly Wednesday partner sync — capture, compliance, set-aside coordination | F15: Continue weekly cadence | G15: Khaalis
A16: 46120 | B16: AG Grace Inc. | C16: Khaalis Wooden, Susan Rouse, Graham | D16: Sync | E16: Weekly Wednesday partner sync — capture, compliance, set-aside coordination | F16: Continue weekly cadence | G16: Khaalis
... A59: 46174 | B59: Thorium One | C59: Khaalis Wooden | D59: Intro | E59: Chad; SDVOSB mgmt consulting / tech broker; Gate 1 kill on all 4 VBX lanes | F59: FILED — no follow-up | G59: Khaalis

Sheet Pipeline
A1: PIPELINE — Active Opportunities
A2: Stage values: Identified | Qualified | Capture | Submitted | Awarded | Lost | No-Bid. Target: 20 active opps at steady state.
A4: Opp ID | B4: Opportunity Name | C4: Agency / Client | D4: NAICS | E4: Stage | F4: Est. Value ($) | G4: Date Identified | H4: Stage Date | I4: Capture Owner | J4: Notes
A5: OPP-001 | B5: Montana AI Products & Services (SPB-RFP-2026-0608GW) — Track 1 | C5: Montana State Procurement | D5: 541511 | E5: Submitted | F5: 2000000 | G5: 46157 | H5: 46170 | I5: Khaalis Wooden | J5: Bid in flight with AG Grace. AI Track 1.
A6: OPP-002 | B6: Maryland Statewide Network Services (BPM054667) FA4 | C6: Maryland DoIT | D6: 541519 | E6: Capture | F6: 5000000 | G6: 46122 | H6: 46137 | I6: Khaalis Wooden | J6: BLOCKED: eMMA registration required. Teaming with AG Grace.
A7: OPP-003 | B7: WA DOH Statewide Rural Health Program (RFP 26-005C) | C7: Washington State DOH | D7: 541512 | E7: Qualified | F7: 1500000 | G7: 46132 | H7: 46147 | I7: Khaalis Wooden | J7: BLOCKED: SOC 2 Type II + WA foreign entity registration.
A8: OPP-004 | B8: Rural Health Transformation Program (RHTP) — Maryland state lane | C8: Maryland Dept of Health / CMS | D8: 541512 | E8: Identified | F8: 3000000 | G8: 46162 | H8: 46162 | I8: Khaalis Wooden | J8: $50B CMS initiative. GRHD framework alignment. Subcontract path TBD.
A9: OPP-005 | B9: Rural Health Transformation Program (RHTP) — Texas state lane | C9: Texas HHS / CMS | D9: 541512 | E9: Identified | F9: 3000000 | G9: 46162 | H9: 46162 | I9: Khaalis Wooden | J9: RHTP Texas. Partner alignment with NCP / BAC for VHA-adjacent.
A10: OPP-006 | B10: CBO "SENTRY" IT Engineering Support (CB26-RFQ0012) | C10: Congressional Budget Office (CBO) | D10: 541519 | E10: Capture | F10: 0 | G10: 46175 | H10: 46178 | I10: Khaalis Wooden | J10: Teaming with The Enterprise Solutions (TES). Network/DevSecOps/Service Desk/Web Security/Cybersecurity DoWs (J2,J3,J6-J9). 12-mo base + 4 option yrs. Value TBD.
A11: OPP-007 | B11: CDC IFMS Services & Support (75D301-26-Q-78924) | C11: Centers for Disease Control and Prevention (CDC) | D11: 541512 | E11: Capture | F11: 0 | G11: 46175 | H11: 46178 | I11: Khaalis Wooden | J11: Teaming with The Enterprise Solutions (TES). NAICS 541512, GSA SIN 54151S, 100% small business set-aside. Base + 4 option yrs (PoP 7/1/2026). Value TBD.
A12: OPP-008 | B12: VA TERPS Support (36C10B26Q0107) | C12: Department of Veterans Affairs (VA) | D12: 541512 | E12: Capture | F12: 0 | G12: 46175 | H12: 46178 | I12: Khaalis Wooden | J12: Teaming with The Enterprise Solutions (TES). TERPS PWS. NOTE: uploaded PDF body mislabeled vs filename - verify PWS scope. NAICS/value TBD.

Sheet Active_Projects
A1: ACTIVE PROJECTS — Post-award execution tracking
A2: Add a row when a contract is awarded. Status values: Active | Paused | Complete | Closeout.
A4: Project ID | B4: Project Name | C4: Client | D4: Contract Type | E4: Value ($) | F4: Start Date | G4: End Date | H4: Status | I4: % Complete | J4: PM / Lead

Sheet Feedback
A1: FEEDBACK LOG — Internal & External
A2: Source: Internal | External. Type: CPARS | Survey | Email | Verbal | Slack. Sentiment: + | 0 | −
A4: Date | B4: Source | C4: Party | D4: Type | E4: Sentiment | F4: Summary | G4: Action Required | H4: Owner

Sheet Screenings
A1: SCREENINGS — All Partner Entities (Source of Truth)
A2: Col E (Screen Date Norm) is the date used by metrics. Edit textual screen dates in col D for display only.
A4: # | B4: Company | C4: Primary Contact | D4: Set-Aside | E4: Screen Date (Norm) | F4: NDA Date | G4: Vertical | H4: Classification | I4: Screen Date (Display)
A5: 1 | B5: AG Grace Inc. | C5: Susan Rouse | D5: SDVOSB / WOSB / CMMC-ATP / C3PAO | E5: 46112 | F5: 46038 | G5: Cyber / Fed Healthcare IT | H5: PRIORITY | I5: Pre-4/1/26
A6: 2 | B6: DataCom Solutions | C6: Jerry Brooks | D6: SDVOSB / HUBZone / 8(a) | E6: 46112 | G6: Federal IT / Cloud | H6: PRIORITY | I6: Pre-4/1/26
A7: 3 | B7: Synovix | C7: Joe Green | D7: SDVOSB | E7: 46112 | G7: Federal IT / Healthcare IT | H7: PRIORITY | I7: Pre-4/1/26
A8: 4 | B8: theta LLC | C8: Mannie Iroanya | D8: 8(a) / HUBZone | E8: 46131 | G8: Fed Healthcare IT (CMS/HHS) | H8: PRIORITY | I8: 4/19/2026
A9: 5 | B9: AgileCare | C9: Marion Vanzie | D9: – (verify) | E9: 46131 | G9: Healthcare IT | H9: PRIORITY | I9: 4/19/2026
A10: 6 | B10: SRFed | C10: Paul Scace | D10: SDVOSB | E10: 46135 | F10: 46148 | G10: Federal IT / GovCon | H10: PRIORITY | I10: 4/23/2026
A11: 7 | B11: Proksi Systems | C11: Riddhi Choksi | D11: 8(a) / WOSB / EDWOSB / HUBZone | E11: 46139 | F11: 46148 | G11: Federal IT / Healthcare IT | H11: PRIORITY | I11: 4/27/2026
A12: 8 | B12: TES Consultants | C12: Elisabeth Nguyen | D12: 8(a) / WOSB / EDWOSB | E12: 46140 | F12: 46141 | G12: Federal IT / Healthcare IT | H12: PRIORITY | I12: 4/28/2026
A13: 9 | B13: SAG / Strategic Alliances Group | C13: Sharon Jacobs | D13: SDVOSB / WOSB / MBE / DBE | E13: 46142 | F13: 46142 | G13: Federal IT / SLED | H13: PRIORITY | I13: 4/30/2026
A14: 10 | B14: ISG / Invicta Solutions Group | C14: – | D14: SDVOSB | F14: 46148 | G14: Federal IT | H14: PRIORITY | I14: –
A15: 11 | B15: OMNI | C15: Jonathan Rendon | D15: SDVOSB | G15: Federal IT / VA | H15: PRIORITY | I15: –
A16: 12 | B16: MTNT | C16: David Shearman | D16: ANC 8(a) – Tribal | E16: 46154 | G16: IHS / HRSA / USDA Rural | H16: PRIORITY | I16: 5/12/2026
A17: 13 | B17: Copper River Technologies | C17: Bradley Halladay | D17: ANC 8(a) – Tribal | E17: 46154 | G17: IHS EHR / Fed Healthcare IT | H17: PRIORITY | I17: 5/12/2026
A18: 14 | B18: West Point Security | C18: Norman Massry | D18: SDVOSB | E18: 46127 | F18: 46127 | G18: Cybersecurity / NY-NJ SLED | H18: PRIORITY | I18: Apr 2026
A19: 15 | B19: Advocate IT | C19: Thomas Duffy | D19: HUBZone / DOBE | E19: 46127 | G19: Federal IT / DoD (Ft. Meade) | H19: PRIORITY | I19: Apr 2026
A20: 16 | B20: Apex Consulting | C20: Jacob Gadd | D20: VOSB | E20: 46139 | F20: 46141 | G20: – | H20: BENCH | I20: 4/27/2026
A21: 17 | B21: NetSecurely | C21: Josh Fonger | D21: – | E21: 46135 | F21: 46139 | G21: – | H21: BENCH | I21: 4/23/2026
A22: 18 | B22: Blue Rose Consulting | C22: Todd Weiler | D22: – | E22: 46139 | G22: – | H22: BENCH | I22: 4/27/2026
A23: 19 | B23: AlphaTango | C23: Anna Olvera | D23: – | E23: 46140 | G23: – | H23: BENCH | I23: 4/28/2026
A24: 20 | B24: GD Resources (GDR) | C24: Basso Ghee | D24: Maryland MBE / DBE / SBE | E24: 46132 | F24: 46142 | G24: – | H24: BENCH | I24: 4/20/2026
A25: 21 | B25: RDE | C25: C. Sullivan | D25: – | E25: 46146 | G25: – | H25: BENCH | I25: 5/4/2026
A26: 22 | B26: CodeCypher | C26: Jeff Holmes | D26: – | E26: 46146 | G26: – | H26: BENCH | I26: 5/4/2026
A27: 23 | B27: Jones & Associates | C27: – | D27: SDVOSB / MBE / DBE | E27: 46112 | G27: – | H27: BENCH | I27: Pre-4/1/26
A28: 24 | B28: HumanEdge | C28: Russell Brown | D28: – | E28: 46127 | G28: – | H28: WATCHLIST | I28: Apr 2026
A29: 25 | B29: HumanEdge | C29: Sharee Legree | D29: – | E29: 46127 | G29: – | H29: WATCHLIST | I29: Apr 2026
A30: 26 | B30: BeehiveTech | C30: Patrick Simon | D30: – | E30: 46127 | G30: – | H30: WATCHLIST | I30: Apr 2026
A31: 27 | B31: IronCloud Government Services | C31: Jeffrey Brown | D31: – | E31: 46134 | F31: 46146 | G31: – | H31: WATCHLIST | I31: 4/22/2026
A32: 28 | B32: TDM Consultants | C32: Tony Macon | D32: – | E32: 46135 | F32: 46159 | G32: – | H32: WATCHLIST | I32: 4/23/2026
A33: 29 | B33: ResilientMind AI | C33: Joseph McGinty | D33: – | E33: 46138 | G33: – | H33: WATCHLIST | I33: 4/26/2026
A34: 30 | B34: SirrahPathways | C34: Sheryl Houston | D34: – | E34: 46146 | G34: – | H34: WATCHLIST | I34: 5/4/2026
A35: 31 | B35: ELCOMM | C35: Ellerbee | D35: – | E35: 46146 | G35: – | H35: WATCHLIST | I35: 5/4/2026
A36: 32 | B36: FailProof Credit | C36: Justin Brown | D36: – | E36: 46127 | G36: – | H36: WATCHLIST | I36: Apr 2026
A37: 33 | B37: RTD | C37: James Wood | D37: – | E37: 46127 | G37: – | H37: FILED | I37: Apr 2026
A38: 34 | B38: Talantage | C38: Tasha Peck | D38: – | E38: 46127 | G38: – | H38: FILED | I38: Apr 2026
A39: 35 | B39: Vonis Consulting | C39: Iwona Przedpelska | D39: – | E39: 46127 | G39: – | H39: FILED | I39: Apr 2026
A40: 36 | B40: CadenceProcurement | C40: Shaneiqua Johnson | D40: – | E40: 46127 | G40: – | H40: FILED | I40: Apr 2026
A41: 37 | B41: KeystoneGeneral | C41: Bryan Read | D41: – | E41: 46127 | G41: – | H41: FILED | I41: Apr 2026
...

Sheet NDAs
A1: NDAs — Executed NDA Register
A2: Col D (NDA Date) is the date used by metrics. Source: Visionblox NDA register.
A4: # | B4: Recipient / Entity | C4: Contact | D4: NDA Date | E4: Document Filename | F4: Status | G4: Partner Classification
A5: 1 | B5: Vonis Consulting | C5: Iwona Przedpelska | D5: 46129 | E5: VBX_NDA_IwonaPrzedpelska_2026-04-17.docx | F5: Executed | G5: FILED
A6: 2 | B6: Cadence Procurement | C6: Shaneiqua Johnson | D6: 46127 | E6: Visionblox_NDA_CadenceProcurement_ShaneiquaJohnson_2026-04.docx | F6: Executed | G6: FILED
A7: 3 | B7: Grit Government Solutions | C7: – | D7: 46127 | E7: Visionblox_NDA_GritGovernmentSolutions_2026-04.docx | F7: Executed | G7: FILED
A8: 4 | B8: Maywell Solutions | C8: Kofoworola Adeoti | D8: 46127 | E8: Visionblox_NDA_MaywellSolutions_2026-04.docx | F8: Executed | G8: FILED
A9: 5 | B9: Candidate Solutions | C9: Linda Wiggins | D9: 46127 | E9: Visionblox_NDA_CandidateSolutions_LindaWiggins_2026-04.docx | F9: Executed | G9: FILED
A10: 6 | B10: Novarens Systems | C10: – | D10: 46127 | E10: Visionblox_NDA_NovarenSystems_2026-04.docx | F10: Executed | G10: FILED
A11: 7 | B11: West Point Security | C11: Norman Massry | D11: 46127 | E11: Visionblox_NDA_WestPointSecurity_2026-04.docx | F11: Executed | G11: PRIORITY
A12: 8 | B12: NetSecurely | C12: Josh Fonger | D12: 46139 | E12: Visionblox_NDA_NetSecurely_2026-04-27.docx | F12: Executed | G12: BENCH
A13: 9 | B13: FortunaBMC | C13: – | D13: 46140 | E13: Visionblox_NDA_FortunaBMC_2026-04-28.docx | F13: Executed | G13: FILED
A14: 10 | B14: TES Consultants (Final) | C14: Elisabeth Nguyen | D14: 46141 | E14: Visionblox_NDA_TESConsultants_2026-04-29_Final.docx | F14: Executed | G14: PRIORITY
A15: 11 | B15: Apex Consulting | C15: Jacob Gadd | D15: 46141 | E15: Visionblox_NDA_ApexConsulting_JacobGadd_2026-04-29.docx | F15: Executed | G15: BENCH
A16: 12 | B16: Strategic Alliances Group (SAG) | C16: Sharon Jacobs | D16: 46142 | E16: Visionblox_NDA_StrategicAlliancesGroup_2026-04-30.docx | F16: Executed | G16: PRIORITY
... A23: 19 | B23: Nacient LLC | C23: Karen Perez Diaz | D23: 46162 | E23: Visionblox_NDA_NacientLLC_2026-05-20.docx | F23: Executed | G23: BENCH

Sheet Agreements
A1: AGREEMENTS — Teaming | Commission | Partnership
A2: Col D (Date) is the date used by metrics. Includes all executed agreements.
A4: # | B4: Party / Entity | C4: Contact | D4: Date | E4: Agreement Type | F4: Document Filename | G4: Status | H4: Notes
A5: 1 | B5: Vonis Consulting | C5: Iwona Przedpelska | D5: 46159 | E5: BD Commission Agreement | F5: VBX_CommissionAgreement_VonisCons_IwonaPrzedpelska_20260517.docx | G5: Executed | H5: BD referral / commission role; Vonis is a FILED partner — referral only
A6: 2 | B6: [Standard Template] | C6: – | E6: BD Commission Agreement — Template | F6: VBX_BDCommissionAgreement_Standard.docx | G6: Template on File | H6: Master template; not yet executed with any active PRIORITY partner
